Workbook

Sheet IMPT INFO
A1: CANONICAL PRICING WORKBOOK
A2: This file is used by the BB pricing app and internal Excel solvers.
A3: Do NOT create numbered versions.
A4: Version history is managed via storage.

Sheet Master Variety List
A1: Season | B1: Category | C1: Flower | D1: Retail Price | E1: Avg. WS Price | F1: Standard Deviation | G1: MVFC | H1: Potomac | I1: SP Guess | J1: USDA W/S | K1: Global Rose | L1: Danisa's | M1: Faire | N1: W/S Flowers.net | O1: MI FF | P1: Horst Flowers | Q1: ASCFG info | S1: retail markup = | T1: 0.5
A2: Summer/Fall | B2: 4 - Floater | C2: Ageratum | D2: =E2*(1+$T$1) -> 1.9425 | E2: =AVERAGE(G2:Q2) -> 1.295 | F2: =STDEV(G2:Q2) -> 0.0070710678 | G2: 1.3 | O2: 1.29
A3: Early Spring, Late Spring | B3: 4 - Floater | C3: Agrostemma | D3: =E3*(1+$T$1) -> 1.5 | E3: =AVERAGE(G3:Q3) -> 1 | F3: =STDEV(G3:Q3) -> #DIV/0! | I3: 1
A4: Late Spring | B4: 2 - Foundation | C4: Allium (S) | D4: =E4*(1+$T$1) -> 2.4 | E4: =AVERAGE(G4:Q4) -> 1.6 | F4: =STDEV(G4:Q4) -> #DIV/0! | O4: 1.6
A5: Late Spring | B5: 5 - Finisher | C5: Allium (M, L) | D5: =E5*(1+$T$1) -> 2.56875 | E5: =AVERAGE(G5:Q5) -> 1.7125 | F5: =STDEV(G5:Q5) -> 0.35677958 | H5: 1.5 | I5: 1.75 | L5: 1.4 | O5: 2.2
A6: Summer/Fall | B6: 5 - Finisher | C6: Amaranth | D6: =E6*(1+$T$1) -> 2.9125 | E6: =AVERAGE(G6:Q6) -> 1.9416667 | F6: =STDEV(G6:Q6) -> 0.56325542 | G6: 1.3 | H6: 1.71 | L6: 1.9 | N6: 1.95 | O6: 1.8 | P6: 2.99
A7: Early Spring | B7: 2 - Foundation | C7: Anemone | D7: =E7*(1+$T$1) -> 3.52875 | E7: =AVERAGE(G7:Q7) -> 2.3525 | F7: =STDEV(G7:Q7) -> 0.27158485 | H7: 1.95 | L7: 2.5 | O7: 2.43 | P7: 2.53
A8: Late Spring | B8: 2 - Foundation | C8: Astilbe - Dark Pink | D8: =E8*(1+$T$1) -> 2.9475 | E8: =AVERAGE(G8:Q8) -> 1.965 | F8: =STDEV(G8:Q8) -> 0.60737139 | G8: 1.1 | H8: 2.3 | L8: 2 | O8: 2.46
A9: Late Spring | B9: 5 - Finisher | C9: Astilbe - Dark Pink | D9: =E9*(1+$T$1) -> 2.9475 | E9: =AVERAGE(G9:Q9) -> 1.965 | F9: =STDEV(G9:Q9) -> 0.60737139 | G9: 1.1 | H9: 2.3 | L9: 2 | O9: 2.46
A10: Late Spring | B10: 5 - Finisher | C10: Astilbe - Pale Pink | D10: =E10*(1+$T$1) -> 2.85375 | E10: =AVERAGE(G10:Q10) -> 1.9025 | F10: =STDEV(G10:Q10) -> 0.795 | G10: 0.75 | H10: 2.4 | L10: 2 | O10: 2.46
A11: Late Spring | B11: 2 - Foundation | C11: Astilbe - Pale Pink | D11: =E11*(1+$T$1) -> 2.85375 | E11: =AVERAGE(G11:Q11) -> 1.9025 | F11: =STDEV(G11:Q11) -> 0.795 | G11: 0.75 | H11: 2.4 | L11: 2 | O11: 2.46
A12: Early Spring, Late Spring | B12: 4 - Floater | C12: Bachelor's Buttons | D12: =E12*(1+$T$1) -> 2.43 | E12: =AVERAGE(G12:Q12) -> 1.62 | F12: =STDEV(G12:Q12) -> 0.63895748 | G12: 1.1 | H12: 1.2 | L12: 2.5 | O12: 1.68
A13: Late Spring | B13: 6 - Foliage | C13: Baptisia (foliage) | D13: =E13*(1+$O$1) -> #VALUE! | E13: =AVERAGE(G13:Q13) -> 1.5 | F13: =STDEV(G13:Q13) -> #DIV/0! | O13: 1.5
A14: Late Spring | B14: 5 - Finisher | C14: Baptisia (flower) | D14: =E14*(1+$O$1) -> #VALUE! | E14: =AVERAGE(G14:Q14) -> 2.01 | F14: =STDEV(G14:Q14) -> #DIV/0! | O14: 2.01
A15: Summer/Fall | B15: 5 - Finisher | C15: Basil (flowering) | D15: =E15*(1+$T$1) -> 1.65 | E15: =AVERAGE(G15:Q15) -> 1.1 | F15: =STDEV(G15:Q15) -> #DIV/0! | I15: 1.1
A16: Summer/Fall | B16: 6 - Foliage | C16: Basil (foliage) | D16: =E16*(1+$T$1) -> 1.65 | E16: =AVERAGE(G16:Q16) -> 1.1 | F16: =STDEV(G16:Q16) -> #DIV/0! | I16: 1.1
A17: Late Spring | B17: 6 - Foliage | C17: Bells of Ireland | D17: =E17*(1+$T$1) -> 1.725 | E17: =AVERAGE(G17:Q17) -> 1.15 | F17: =STDEV(G17:Q17) -> 0.08660254 | H17: 1.1 | N17: 1.25 | P17: 1.1
A18: Late Spring | B18: 5 - Finisher | C18: Bells of Ireland | D18: =E18*(1+$T$1) -> 1.725 | E18: =AVERAGE(G18:Q18) -> 1.15 | F18: =STDEV(G18:Q18) -> 0.08660254 | H18: 1.1 | N18: 1.25 | P18: 1.1
A19: Summer/Fall | B19: 5 - Finisher | C19: Blueberry branch | D19: =E19*(1+$O$1) -> #VALUE! | E19: =AVERAGE(G19:Q19) -> 3.75 | F19: =STDEV(G19:Q19) -> #DIV/0! | O19: 3.75
A20: Summer/Fall | B20: 5 - Finisher | C20: Blackberry berries (unripe) | D20: =E20*(1+$T$1) -> 2.5875 | E20: =AVERAGE(G20:Q20) -> 1.725 | F20: =STDEV(G20:Q20) -> 0.31819805 | I20: 1.5 | O20: 1.95
A21: Late Spring | B21: 5 - Finisher | C21: Bleeding Heart | D21: =E21*(1+$T$1) -> 2.305 | E21: =AVERAGE(G21:Q21) -> 1.5366667 | F21: =STDEV(G21:Q21) -> 0.96256602 | G21: 0.75 | I21: 1.25 | O21: 2.61
A22: Summer/Fall | B22: 3 - Filler | C22: Brain Celosia | D22: =E22*(1+$T$1) -> 2.5 | E22: =AVERAGE(G22:Q22) -> 1.6666667 | F22: =STDEV(G22:Q22) -> 0.23094011 | G22: 1.4 | H22: 1.8 | I22: 1.8
A23: Late Spring | B23: 3 - Filler | C23: Bupleurum | D23: =E23*(1+$T$1) -> 2.125 | E23: =AVERAGE(G23:Q23) -> 1.4166667 | F23: =STDEV(G23:Q23) -> 0.38188131 | H23: 1 | N23: 1.5 | O23: 1.75
A24: Early Spring, Late Spring | B24: 4 - Floater | C24: Ranunculus, Butterfly | D24: =E24*(1+$T$1) -> 3.75 | E24: =AVERAGE(G24:Q24) -> 2.5 | F24: =STDEV(G24:Q24) -> 0.5 | H24: 3 | I24: 2 | L24: 2.5
A25: Early Spring, Late Spring | B25: 4 - Floater | C25: Calendula | D25: =E25*(1+$O$1) -> #VALUE! | E25: =AVERAGE(G25:Q25) -> 1.5 | F25: =STDEV(G25:Q25) -> #DIV/0! | O25: 1.5
A26: Late Spring, Summer/Fall | B26: 2 - Foundation | C26: Carnation | D26: =E26*(1+$O$1) -> #VALUE! | E26: =AVERAGE(G26:Q26) -> 0.864 | F26: =STDEV(G26:Q26) -> 0.23532956 | H26: 0.89 | J26: 0.63 | L26: 0.95 | N26: 1.2 | P26: 0.65
A27: Late Spring | B27: 5 - Finisher | C27: Campanula | D27: =E27*(1+$T$1) -> 2.51 | E27: =AVERAGE(G27:Q27) -> 1.6733333 | F27: =STDEV(G27:Q27) -> 0.41064989 | G27: 1.25 | H27: 1.7 | O27: 2.07
A28: Summer/Fall | B28: 3 - Filler | C28: Celosia -- Brain | D28: =E28*(1+$O$1) -> #VALUE! | E28: =AVERAGE(G28:Q28) -> 1.75 | F28: =STDEV(G28:Q28) -> #DIV/0! | I28: 1.75
A29: Summer/Fall | B29: 2 - Foundation | C29: Celosia -- Plume | D29: =E29*(1+$O$1) -> #VALUE! | E29: =AVERAGE(G29:Q29) -> 1.975 | F29: =STDEV(G29:Q29) -> 0.83416625 | G29: 1.4 | H29: 1.8 | L29: 3.2 | O29: 1.5
A30: Summer/Fall | B30: 3 - Filler | C30: Celosia -- Flamingo (spray) | D30: =E30*(1+$T$1) -> 2.325 | E30: =AVERAGE(G30:Q30) -> 1.55 | F30: =STDEV(G30:Q30) -> 0.17320508 | G30: 1.4 | H30: 1.8 | I30: 1.5 | O30: 1.5
A31: Late Spring | B31: 3 - Filler | C31: Clarkia | D31: =E31*(1+$O$1) -> #VALUE! | E31: =AVERAGE(G31:Q31) -> 1.86 | F31: =STDEV(G31:Q31) -> #DIV/0! | O31: 1.86
A32: Late Spring, Summer/Fall | B32: 5 - Finisher | C32: Clematis | D32: =E32*(1+$O$1) -> #VALUE! | E32: =AVERAGE(G32:Q32) -> 2.6666667 | F32: =STDEV(G32:Q32) -> 1.3316656 | H32: 2 | L32: 1.8 | O32: 4.2
A33: Summer/Fall | B33: 1 - Focal | C33: Chrysanthemum (L) | D33: =E33*(1+$O$1) -> #VALUE! | E33: =AVERAGE(G33:Q33) -> 1.65 | F33: =STDEV(G33:Q33) -> 0.6363961 | N33: 1.2 | O33: 2.1
A34: Summer/Fall | B34: 2 - Foundation | C34: Chrysanthemum (M or spray) | D34: =E34*(1+$O$1) -> #VALUE! | E34: =AVERAGE(G34:Q34) -> 1.55 | F34: =STDEV(G34:Q34) -> 0.77781746 | N34: 1 | O34: 2.1
A35: Summer/Fall | B35: 4 - Floater | C35: Cosmos | D35: =E35*(1+$T$1) -> 2.49 | E35: =AVERAGE(G35:Q35) -> 1.66 | F35: =STDEV(G35:Q35) -> 0.19697716 | G35: 1.6 | L35: 1.5 | O35: 1.88
A36: Late Spring, Summer/Fall | B36: 5 - Finisher | C36: Cress | D36: =E36*(1+$T$1) -> 1.95 | E36: =AVERAGE(G36:Q36) -> 1.3 | F36: =STDEV(G36:Q36) -> 0.28284271 | I36: 1.1 | O36: 1.5
A37: Early Spring | B37: 2 - Foundation | C37: Daffodil (single large flower) | D37: =E37*(1+$T$1) -> 2.37 | E37: =AVERAGE(G37:Q37) -> 1.58 | F37: =STDEV(G37:Q37) -> 0.32046841 | H37: 1.6 | I37: 1.25 | O37: 1.89
A38: Early Spring | B38: 3 - Filler | C38: Daffodil (spray form) | D38: =E38*(1+$T$1) -> 2.355 | E38: =AVERAGE(G38:Q38) -> 1.57 | F38: =STDEV(G38:Q38) -> 0.45254834 | I38: 1.25 | O38: 1.89
A39: Summer/Fall | B39: 2 - Foundation | C39: Daisy | D39: =E39*(1+$O$1) -> #VALUE! | E39: =AVERAGE(G39:Q39) -> 1.5 | F39: =STDEV(G39:Q39) -> #DIV/0! | O39: 1.5
A40: Summer/Fall | B40: 1 - Focal | C40: Dahlia (L) | D40: =E40*(1+$T$1) -> 6.15 | E40: =AVERAGE(G40:Q40) -> 4.1 | F40: =STDEV(G40:Q40) -> 0.36055513 | H40: 3.8 | L40: 4 | O40: 4.5
...

Sheet version info
A1: last updated | B1: added to Master List | C1: source date (if cited)
A2: USDA | B2: 2.7.2026 | C2: 46049
A3: Potomac w/s | B3: 2.7.2026
A4: Danisa's | B4: 2.7.2026
B5: 2.7.2026
A6: W/S Flowers.net | B6: 2.7.2026
A7: MI FF | B7: 2.7.2026 | C7: 45705
A8: Horst | B8: 2.7.2026

Sheet Averages
B2: Early Spring | C2: Late Spring | D2: Summer/Fall
A3: Focals
A4: Foundations
A5: Filler
A6: Floater
A7: Finisher
A8: Foliage

Sheet Early Spring
A1: Season | B1: (Multiple Items) | I1: total # of regular market bouquets desired = | J1: 30
A3: Row Labels | E3: Calculated quantity of flowers in bouquet | F3: total number of stems used | I3: average wholesale price for category | J3: Availability (# stems) | L3: # stems leftover
A4: 1 - Focal | C4: Early Spring | D4: =SUMPRODUCT(I4:I9, E4:E9) -> 22.894735 | E4: 3 | F4: =$J$1*E4 -> 90 | H4: focal | I4: =AVERAGEIFS('Master Variety List'!E:E, 'Master Variety List'!A:A, "*Early Spring*", 'Master Variety List'!B:B, "*Focal*") -> 2.5036667 | J4: 500 | L4: =J4-F4 -> 410 | M4: 3 | N4: 4 | O4: 3
A5: Tulip - Double | E5: 5 | F5: =$J$1*E5 -> 150 | H5: foundation | I5: =AVERAGEIFS('Master Variety List'!E:E, 'Master Variety List'!A:A, "*Early Spring*", 'Master Variety List'!B:B, "*Foundation*") -> 1.83875 | J5: 700 | L5: =J5-F5 -> 550 | M5: 8 | N5: 10 | O5: 12
A6: Tulip - French | E6: 1 | F6: =$J$1*E6 -> 30 | H6: filler | I6: =AVERAGEIFS('Master Variety List'!E:E, 'Master Variety List'!A:A, "*Early Spring*", 'Master Variety List'!B:B, "*Filler*") -> 1.6676042 | J6: 100 | L6: 100 | O6: 0
A7: Tulip - Regular | E7: 1 | F7: =$J$1*E7 -> 30 | H7: floater | I7: =AVERAGEIFS('Master Variety List'!E:E, 'Master Variety List'!A:A, "*Early Spring*", 'Master Variety List'!B:B, "*Float*") -> 1.5766667 | J7: 400 | L7: =J7-F7 -> 370 | N7: 1 | O7: 0
A8: 2 - Foundation | E8: 0 | F8: =$J$1*E8 -> 0 | H8: finisher | I8: =AVERAGEIFS('Master Variety List'!E:E, 'Master Variety List'!A:A, "*Early Spring*", 'Master Variety List'!B:B, "*Finisher*") -> 2.0083333 | J8: 25 | L8: =J8-F8 -> 25 | N8: 2 | O8: 2
A9: Anemone | E9: 2 | F9: =$J$1*E9 -> 60 | H9: foliage | I9: =AVERAGEIFS('Master Variety List'!E:E, 'Master Variety List'!A:A, "*Early Spring*", 'Master Variety List'!B:B, "*Foliage*") -> 1.4728571 | J9: 150 | L9: =J9-F9 -> 90 | M9: 2 | N9: 2 | O9: 2
A10: Hellebore
A11: Orlaya
A12: Poppy - Icelandic (M-L) | F12: 1. Fill in the cells in pink. Do NOT adjust any other values
A13: Ranunculus | F13: 2. Run "solver". Go to the "Data" tab.
A14: Daffodil (single large flower) | F14: 3. Click on cell D4-D9 (it is a merged cell)
A15: 3 - Filler | F15: 4. In the upper right, click on "Analysis Tools". Note: if you see "Solver" in the upper right, you can skip this step.
A16: Saponaria | F16: 5. Check the box for "Solver."
A17: Stock | F17: 6. Hit "Solve" in the lower right
A18: Daffodil (spray form)
A19: Duetzia | F19: FOCAL | G19: FOUNDATION | O19: FILLER | Q19: FLOATER | U19: FINISHER | W19: FOLIAGE
A20: Pieris | B20: Make this when… | C20: Never, Ever: | F20: tulip (large) | G20: small tulip | H20: anemone | I20: daffodil | J20: hellebore | K20: orlaya | L20: poppy | M20: Ranunculus | N20: Stock | O20: Daffodil Spray | P20: Saponaria | Q20: Agrostemma | R20: Bach Buttons | S20: small poppy | T20: Nigella | U20: Papyrus | V20: Mint | W20: Privet | X20: Euonymous
A21: 4 - Float | D21: Spring -- Light or Muted
A22: Agrostemma | D22: Peaches & Cream | E22: Warm: peach, cream, white | F22: Apricot Parrot, Super Parrot, Charming Beauty | G22: Clearwater | H22: White | I22: white, salmon | J22: white | K22: white | L22: peach, white | M22: Salmon, cream, white | N22: peach, white | O22: White | Q22: white | S22: peach, white, pale yellow | T22: white
A23: Bachelor's Buttons | D23: Easter Basket | E23: muted: pink, peach, yellow, pale purple | F23: Foxtrot, Apricot Parrot, Design Impression, Double Price, Charming Beauty, Blue Diamond | H23: Pastel Pink, Pastel Purple | I23: white, salmon | J23: pink | L23: peach, pale yellow, light pink | M23: Chamallow, Salmon, cream, purple jean | N23: peach, light pink, pale pale yellow, purple | O23: White | Q23: white | R23: pink | S23: Peach, light pink, pale yellow
A24: Iceland poppy (small) | D24: Sugar Plum Fairy | E24: Warm: Plum, purple, white | F24: Blue Diamond, Super Parrot, Double Price? | G24: Clearwater | H24: Pastel purple | I24: white | J24: purple | L24: white | M24: Purple Jean, Violet | N24: pale purple | Q24: purple | S24: white | T24: white
A25: Nigella | D25: Semi Precious | E25: muted pinks and purples | F25: Foxtrot, Pink Vision Parrot, Blue Diamond | H25: Pale blue, pale pink | I25: white | J25: pink | M25: Chamallow, Purple Jean | N25: pink | R25: light blue, pink | S25: Light pink | T25: blue
A26: 5 - Finisher | D26: Champagne Brunch | E26: Warm: Yellow, peach, pale pink, white/cream | F26: Foxtrot, Apricot Parrot, Design Impression, Super Parrot, Charming Beauty | G26: Clearwater | H26: White | I26: white | L26: peach, pale yellow, light pink | M26: Chamallow, Salmon, white, cream | N26: peach, light pink, pale yellow | Q26: white | S26: Peach, light pink, pale yellow | T26: white
A27: Mint | D27: Mellow Unicorn | E27: warm/cool mix: Pink, salmon, peach, blue/purple | F27: Foxtrot, blue diamond, Amazing Grace, Apricot Parrot, Design Impression, Pink Vision Parrot, Double Price | H27: Pastel pink or Pastel purple | I27: white, salmon | L27: peach, light pink | M27: Chamallow, Salmon | N27: peach, light pink, pale purple | R27: light blue, pink | S27: light pink, peach | T27: light blue
A28: Papyrus | D28: Butter, biscuits and Honey | E28: Warm: Pale Yellow, gold, white | F28: Charming Beauty, Super Parrot | G28: Clearwater | H28: White | I28: white | L28: pale yellow, white | M28: Cream, gold, white | N28: peach, pale yellow, white | O28: white | Q28: white | S28: Peach, pale yellow | T28: white
A29: 6 - Foliage
A30: Euonymous | D30: Spring -- Bright or Deep
A31: Honeysuckle | D31: Birthday cake | E31: Hot: pink, gold, orange, white | F31: Foxtrot, Amazing Grace, Dordogne, Pink Vision Parrot, Super Parrot, Yosemite | G31: Clearwater, Apricot Impression | H31: White | I31: white | L31: Pink, orange, bright yellow, white | M31: pink, gold, orange | N31: white, pink | Q31: white | R31: pink | S31: orange, pink, white, gold
A32: Privet | D32: Candy Crush | E32: Warm or cool: all pinks | F32: Foxtrot, Amazing Grace, Dordogne, Pink Vision Parrot, Avignon, Yosemite | H32: Bright pink | M32: Bonbon, Barby, Pink, Rose | N32: pink | Q32: white | R32: all pinks | S32: pink
A33: Nandina foliage | D33: Cover Grrl | E33: Cool or hot: Red, pinks | F33: Red Princess, Uncle Tom, Yosemite, Amazing Grace, Dordogne, Pink Vision Parrot, Avignon | H33: Red, Bright Pink | I33: none | L33: Pink | M33: Red, Bonbon, Barby, Pink, Rose | N33: pink | Q33: white | R33: pink | S33: pink
A34: Mint (foliage) | D34: Rainbow Sherbet | E34: Hot: peach, orange, pink, white | F34: Dordogne!!!Foxtrot, Menton, Amazing Grace, Avignon, Super Parrot | G34: Clearwater, Apricot Impression | I34: white, salmon | L34: Pink, orange, white | M34: Pink, Rose, Orange, White | N34: pink, white | Q34: white | R34: pink | S34: pink, orange | T34: white
A35: Grand Total | D35: Fruit Salad | E35: Cool or hot: bright multi | F35: Red Princess, Uncle Tom, Yosemite, Dordogne, Blue Diamond | G35: Apricot Impresion | H35: Red | I35: white | L35: pink, orange, bright yellow, white | M35: Bonbon, Barby, Pink, Rose, Red, Orange, Purple Jean | N35: pink | Q35: purple | R35: pink | S35: pink, orange, gold, white | T35: white
D36: Electric Unicorn | E36: Hot and Cool: pink, orange, blue/purple | F36: Yosemite, Foxtrot, Amazing Grace, Dordogne, Pink Vision Parrot, Avignon, Blue Diamond | G36: Apricot Impresion | H36: Blue | L36: pink, orange, white | M36: pink, rose, orange | N36: light purple, pink | R36: blue | S36: pink, light orange | T36: Blue
D37: Firecracker | E37: Hot: Red, bright pink, orange, gold | F37: Red Princess, Uncle Tom, Avignon!!, Yosemite, Amazing Grace, Dordogne | G37: Apricot Impresion | H37: Red, Bright pink | L37: yellow, orange | M37: Red, orange, gold | N37: warm pink | R37: pink | S37: orange, gold
D38: Northern Lights | E38: Cool: pink and blue | F38: Foxtrot, Amazing Grace, Pink Vision Parrot, Yosemite, Blue Diamond | H38: Dark Blue, Bright Pink | M38: Bonbon, Barby, Pink, Rose | N38: pink | R38: blue | S38: pink | T38: blue

Sheet Late Spring
A1: Season | B1: (Multiple Items) | J1: total # of regular market bouquets desired = | K1: 5
A3: Row Labels | F3: Calculated quantity of flowers in bouquet | G3: total number of stems used | J3: average wholesale price for category | K3: Availability (# stems) | M3: # stems leftover
A4: 1 - Focal | D4: Late Spring | E4: =SUMPRODUCT(F4:F9, J4:J9) -> 58.764747 | F4: 6 | G4: =$K$1*F4 -> 30 | I4: focal | J4: =AVERAGEIFS('Master Variety List'!E:E, 'Master Variety List'!A:A, "*Late Spring*", 'Master Variety List'!B:B, "*Focal*") -> 3.5614583 | K4: 500 | M4: =K4-G4 -> 470
A5: Delphinium | F5: 7.000022 | G5: =$K$1*F5 -> 35.00011 | I5: foundation | J5: =AVERAGEIFS('Master Variety List'!E:E, 'Master Variety List'!A:A, "*Late Spring*", 'Master Variety List'!B:B, "*Foundation*") -> 1.6612667 | K5: 1711 | M5: =K5-G5 -> 1675.9999
A6: Garden Rose | F6: 5 | G6: =$K$1*F6 -> 25 | I6: filler | J6: =AVERAGEIFS('Master Variety List'!E:E, 'Master Variety List'!A:A, "*Late Spring*", 'Master Variety List'!B:B, "*Filler*") -> 1.6491111 | K6: 264 | M6: =K6-G6 -> 239
A7: Peony - Coral Charm | F7: 6 | G7: =$K$1*F7 -> 30 | I7: floater | J7: =AVERAGEIFS('Master Variety List'!E:E, 'Master Variety List'!A:A, "*Late Spring*", 'Master Variety List'!B:B, "*Float*") -> 1.4819231 | K7: 83 | M7: =K7-G7 -> 53
A8: Peony - Dark Pink | F8: 0 | G8: =$K$1*F8 -> 0 | I8: finisher | J8: =AVERAGEIFS('Master Variety List'!E:E, 'Master Variety List'!A:A, "*Late Spring*", 'Master Variety List'!B:B, "*Finisher*") -> 1.7894792 | K8: 30 | M8: =K8-G8 -> 30
A9: Peony - Pale Pink/Blush | F9: 6 | G9: =$K$1*F9 -> 30 | I9: foliage | J9: =AVERAGEIFS('Master Variety List'!E:E, 'Master Variety List'!A:A, "*Late Spring*", 'Master Variety List'!B:B, "*Foliage*") -> 1.4383333 | K9: 1000 | M9: =K9-G9 -> 970
A10: Peony - Pink | F10: =SUM(F4:F9) -> 30.000022
A11: Peony - White
A12: 2 - Foundation | G12: 1. Fill in the cells in lavender. Do NOT adjust any other values
A13: Astilbe - Dark Pink | G13: 2. Run "solver". Go to the "Data" tab.
A14: Astilbe - Pale Pink | G14: 3. Click on cell D4-D9 (it is a merged cell)
A15: Campanula | G15: 4. In the upper right, click on "Analysis Tools". Note: if you see "Solver" in the upper right, you can skip this step.
A16: Garden Rose | G16: 5. Check the box for "Solver."
A17: Larkspur | G17: 6. Hit "Solve" in the lower right
A18: Lilac
A19: Lupine | F19: FOCAL | J19: FOUNDATION | V19: FILLER | AA19: FLOATER | AH19: FINISHER | AN19: FOLIAGE
A20: Poppy - Icelandic (M-L) | B20: Make this when… | C20: Never, Ever: | F20: Delphinium | G20: Peony | H20: Tulip | I20: Ranunculus | J20: Astilbe | K20: Campanula | L20: Rose | M20: Larkspur | N20: Lilac | O20: Lupine | P20: Poppy | Q20: Rudbeckia | R20: Fama Scabiosa | S20: Snapdragon | T20: Stock | U20: Feverfew | V20: Bupleurum | W20: Mockorange | X20: Statice | Y20: Yarrow | Z20: Saponaria | AA20: Agrostemma | AB20: Bachelor Button | AC20: Scabiosa | AD20: Geum | AE20: Iceland Poppy (S) | AF20: Nigella | AG20: Bleeding Heart | AH20: Papyrus | AI20: Fennel | AJ20: Allium | AK20: Dogwood | AL20: Honeysuckle | AM20: Mint | AN20: Euonymous | AO20: Snowball Foliage | AP20: Privet
A21: Queen Anne's / Ammi | D21: Late Spring
A22: Ranunculus | D22: Blushing Beauty | E22: salmon, pale pink, white/cream
A23: Rudbeckia | D23: Easter Basket | E23: pale multi
A24: Scabiosa (Fama) | B24: the hellebores and the purple ranunculus overlap | D24: Sugar Plum Fairy | E24: Plum, purple, white
A25: Snapdragon (L) | D25: Champagne Brunch | E25: Yellow, peach, blush, white/cream
A26: Snapdragon (S) | D26: Mellow Unicorn | E26: Pink, salmon, peach, soft yellow, blue/purple
A27: 3 - Filler | D27: Butter, biscuits and Honey | E27: Warm: Pale Yellow, gold, white
A28: Bupleurum | D28: Semi Precious | E28: muted pinks and purples
A29: Feverfew | D29: Late Spring
A30: Mock Orange | D30: Birthday cake | E30: pink, yellow, orange
A31: Saponaria | D31: Candy Crush | E31: pink
A32: Statice | C32: add white | D32: Cover Grrl | E32: Red, pink,
A33: Stock | D33: Rainbow Sherbet | E33: peach, orange, pink, white
A34: Yarrow | C34: add white | D34: Firecracker | E34: Red, bright pink, orange, gold
A35: Godetia | B35: the Coral Charm peonies and Rudbeckia overlap | D35: Sunkissed | E35: Salmon and Gold | F35: No | G35: Coral Charm | H35: Apricot, Salmon | I35: Dark Salmon, Gold | J35: Dark Pink | K35: No | L35: Apricot, Salmon | M35: No | N35: No | O35: Red | P35: Peach, coral | Q35: Goldilocks, any gold | R35: No | S35: No | T35: Stox Champagne | U35: mini daisy | V35: Yes | W35: No | X35: No | Y35: No | Z35: Peach | AA35: No | AB35: No | AC35: No | AD35: peach | AE35: Coral, peach | AF35: No | AG35: yes | AH35: Yes | AI35: Yes | AJ35: No | AK35: No | AL35: Yes | AM35: Yes | AN35: Yes | AO35: Yes | AP35: Yes | AQ35: Yes
A36: Duetzia
A37: 4 - Float
A38: Agrostemma
A39: Bachelor's Buttons
A40: Geum
A41: Iceland poppy (small)
...

Sheet Summer
A1: Season | B1: (Multiple Items) | J1: total # of regular market bouquets desired = | K1: 50
A3: Row Labels | F3: Calculated quantity of flowers in bouquet | G3: total number of stems used | J3: average wholesale price for category | K3: Availability (# stems) | O3: # stems leftover
A4: 1 - Focal | D4: Summer | E4: =SUMPRODUCT(J4:J9, F4:F9) -> 39.527725 | F4: 3 | G4: =$K$1*F4 -> 150 | I4: focal | J4: =AVERAGEIFS('Master Variety List'!E:E, 'Master Variety List'!A:A, "*Summer*", 'Master Variety List'!B:B, "*Focal*") -> 2.6453333 | K4: 500 | O4: =K4-G4 -> 350
A5: Dahlia (L) | F5: 10 | G5: =$K$1*F5 -> 500 | I5: foundation | J5: =AVERAGEIFS('Master Variety List'!E:E, 'Master Variety List'!A:A, "*Summer*", 'Master Variety List'!B:B, "*Foundation*") -> 1.6591883 | K5: 2000 | O5: =K5-G5 -> 1500
A6: Delphinium FINISHER! | F6: 3 | G6: =$K$1*F6 -> 150 | I6: filler | J6: =AVERAGEIFS('Master Variety List'!E:E, 'Master Variety List'!A:A, "*Summer*", 'Master Variety List'!B:B, "*Filler*") -> 1.6082895 | K6: 500 | O6: =K6-G6 -> 350
A7: Garden Rose | F7: 3 | G7: =$K$1*F7 -> 150 | I7: float | J7: =AVERAGEIFS('Master Variety List'!E:E, 'Master Variety List'!A:A, "*Summer*", 'Master Variety List'!B:B, "*Float*") -> 1.3608333 | K7: 500 | O7: =K7-G7 -> 350
A8: Sunflower (M-L) | F8: 1 | G8: =$K$1*F8 -> 50 | I8: finisher | J8: =AVERAGEIFS('Master Variety List'!E:E, 'Master Variety List'!A:A, "*Summer*", 'Master Variety List'!B:B, "*Finisher*") -> 1.7747807 | K8: 50 | O8: =K8-G8 -> 0
A9: Zinnia (XL) | F9: 3 | G9: =$K$1*F9 -> 150 | I9: foliage | J9: =AVERAGEIFS('Master Variety List'!E:E, 'Master Variety List'!A:A, "*Summer*", 'Master Variety List'!B:B, "*Foliage*") -> 1.4392308 | K9: 150 | O9: =K9-G9 -> 0
A10: 2 - Foundation
A11: Celosia
A12: Dahlia (M) | G12: 1. Fill in the cells in yellow. Do NOT adjust any other values
A13: Dahlia (S) | G13: 2. Run "solver". Go to the "Data" tab.
A14: Echinacea | G14: 3. Click on cell D4-D9 (it is a merged cell)
A15: Garden Rose | G15: 4. In the upper right, click on "Analysis Tools". Note: if you see "Solver" in the upper right, you can skip this step.
A16: Lisianthus | G16: 5. Check the box for "Solver."
A17: Lupine | G17: 6. Hit "Solve" in the lower right | M17: Echo White | N17: Corelli Apricot | P17: Nightengale (deep pink)
A18: Queen Anne's / Ammi | M18: Chroma Yellow | N18: Corelli Rose (med pink) | P18: Doublini (white)
A19: Rudbeckia | M19: Voyage (lt. apricot) | N19: Celeb Madonna (lt + med. pink) | P19: Blue??
A20: Scabiosa (Fama) | F20: FOCAL | J20: FOUNDATION | V20: FILLER | AA20: FLOATER | AG20: FINISHER | AM20: FOLIAGE
A21: Snapdragon (L) | B21: Make this when… | C21: Never, Ever: | F21: Delphinium | G21: Sunflower | H21: Zinnia (XL) | I21: Dahlia | J21: Sunflower (S) | K21: Zinnia (M) | L21: Plume Celosia | M21: Echinacea | N21: Lisianthus | O21: Lupine | P21: Rudbeckia | Q21: Fama Scabiosa | R21: Snapdragon | S21: Strawflower | T21: Marigold | U21: Daisy | V21: Feverfew | W21: Brain Celosia | X21: Hydrangea | Y21: Statice | Z21: Yarrow | AA21: Ageratum | AB21: Cosmos | AC21: Gomphrena | AD21: Scabiosa | AE21: Verbena | AF21: Zinnia (XS) | AG21: Amaranth | AH21: Papyrus | AI21: Fennel | AJ21: Frosted Explosion | AK21: Jewels of Opar | AL21: Honeysuckle | AM21: Geranium | AN21: Raspberry | AO21: Snowball Foliage | AP21: Eucalyptus
A22: Snapdragon (S) | D22: Summer Light
A23: Strawflower | C23: cream Chamallow | D23: Semi Precious | E23: muted pinks and purples | F23: No | G23: No | H23: Lt. pink, Benary lilac | I23: CAL, RRA, Lavenders | J23: No | K23: Pink, lilac, QLR | L23: Pinks | M23: No | N23: Celeb Madonna, Nightengale, Light purple | O23: peach, white | P23: No | Q23: No | R23: Pink | S23: Pink | T23: No | U23: No | V23: No | W23: No | X23: Pink, warm purple | Y23: Rose | Z23: Cool pink | AA23: No | AB23: Cupcake Pink | AC23: Light purple | AD23: Medium Pink | AE23: Yes | AF23: No | AG23: No | AH23: Yes | AI23: No | AJ23: Yes | AK23: No | AL23: Yes | AM23: Yes | AN23: Yes | AO23: Yes | AP23: Yes
A24: Zinnia (M-L) | D24: Butter, Biscuits & Honey | E24: pale multi | F24: White | G24: White Lite, White Nite, Orange | H24: Golden Hour | I24: White, Cornel Bronze | J24: White Lite, White Nite, Gold | K24: Golden Hour, Creamy Yellow, QLO, QLP | L24: No | M24: Yellow | N24: Cream (Yellow), White | O24: No | P24: Goldilocks | Q24: White | R24: White | S24: No | T24: Pale Yellow | U24: Yes | V24: Yes | W24: Gold | X24: Limelight | Y24: No | Z24: No | AA24: No | AB24: White | AC24: No | AD24: Cream, White | AE24: No | AF24: Gold | AG24: Gold | AH24: Yes | AI24: Yes | AJ24: Yes | AK24: No | AL24: Yes | AM24: Yes | AN24: Yes | AO24: Yes | AP24: No
A25: Marigold | D25: Champagne Brunch | E25: Light pink, peach, cream | F25: No | G25: White Lite, White Nite | H25: Pale Pink, Light Salmon, Golden Hour | I25: CAL, RRA, peach | J25: White Lite, White Nite | K25: Pale Pink, Light Salmon, Golden Hour, QLO, QLP | L25: Gold, soft pink | M25: Yellow, Peach | N25: Champagne, Light Pink, Apricot, Cream (Yellow) | O25: No | P25: No | Q25: No | R25: Light Pink, White | S25: Apricot | T25: Pale Yellow | U25: Yes | V25: Yes | W25: Gold | X25: Limelight | Y25: No | Z25: Peach | AA25: No | AB25: White | AC25: No | AD25: Cream, White, Light Pink | AE25: No | AF25: Light Salmon | AG25: Gold | AH25: Yes | AI25: No | AJ25: Yes | AK25: Yes | AL25: Yes | AM25: Yes | AN25: Yes | AO25: Yes | AP25: Yes
A26: Thistle | B26: Oklahoma salmon zinnias are available | D26: Mellow Unicorn | E26: Pink, salmon, blue | F26: Lt. Blue | G26: No | H26: Pink, Light Salmon | I26: other clear pink, salmon | K26: Oklahoma Salmon, Oklahoma Pink | L26: Medium Pink (not fuschia) | M26: Salmon | N26: Champagne, Pink, Apricot | O26: Blue (light) | P26: No | Q26: Blue | R26: Pink, Orange? | S26: Pink, Orange, Salmon | T26: No | U26: No | V26: Yes | W26: No | X26: Blue, pink | Y26: Rose, light blue | Z26: Medium Pink | AA26: Yes | AB26: No | AC26: No | AD26: Blue | AE26: No | AF26: Salmon, pink | AG26: No | AH26: Yes | AI26: No | AJ26: Yes | AK26: Yes | AL26: Yes | AM26: Yes | AN26: Yes | AO26: Yes | AP26: Yes
A27: 2 -Foundation | B27: Nightengale lisis are available | D27: Rose All Day | E27: muted pink | F27: No | G27: No | H27: pale pinks | I27: CAL, RRA | J27: No | K27: pale pinks, QLR | L27: No | M27: No | N27: Pink, Nightengale | O27: No | P27: No | Q27: No | R27: pale pink | S27: Pink | T27: No | U27: No | V27: No | W27: No | X27: Pink | Y27: Rose | Z27: Pink | AA27: No | AB27: Cupcake Pink | AC27: No | AD27: Pink | AE27: No | AF27: No | AG27: Burgundy | AH27: Yes | AI27: No | AJ27: Yes | AK27: Yes | AL27: Yes | AM27: Yes | AN27: Yes | AO27: Yes | AP27: Yes
A28: Sunflower (S) | D28: Summer Bright
A29: 3 - Filler | D29: Birthday cake | E29: pink, gold, orange, white | F29: White | G29: Orange | H29: Benary Bright Pink, Benary Orange | I29: Doris Duke, other clear pink, orange | J29: Orange | K29: Bright Pink, Orange, Gold | L29: Bright pink (not purple-y), orange | M29: Bright gold | N29: White, Corelli Rose? | O29: Red | P29: Goldilocks | Q29: White | R29: Pink, orange, white | S29: Pink, orange | T29: Orange | U29: yes | V29: Yes | W29: Pink, Orange | X29: Limelight | Y29: No | Z29: Pink | AA29: No | AB29: White | AC29: Bright Pink, Orange | AD29: White, pink | AE29: No | AF29: Bright Pink, Orange, Gold | AG29: No | AH29: Yes | AI29: Yes | AJ29: Yes | AK29: No | AL29: Yes | AM29: Yes | AN29: Yes | AO29: Yes | AP29: No
A30: Feverfew | D30: Electric Unicorn | E30: pink, Coral, blue | F30: Blue | G30: No | H30: Benary Bright Pink, Coral, bright salmon | I30: Doris Duke, other clear pink, salmon | J30: No | K30: Pink, Coral | L30: Bright pink (not purple-y), orange, salmon | M30: Salmon | N30: pink, light blue | O30: Blue | P30: No | Q30: Blue | R30: pink, orange? | S30: Pink, coral, orange | T30: No | U30: No | V30: No | W30: Pink | X30: Blue | Y30: Blue | Z30: Pink, Coral | AA30: Yes | AB30: No | AC30: No | AD30: Pink, blue | AE30: No | AF30: Pink, Coral, Gold | AG30: No | AH30: Yes | AI30: No | AJ30: Yes | AK30: No | AL30: Yes | AM30: Yes | AN30: Yes | AO30: Yes | AP30: No
A31: Greek Oregano | C31: add white | D31: Cover Grrl | E31: Red, pink, | F31: No | G31: No | H31: Benary Bright Pink, all pinks, Benary Red | I31: Cornel, Doris Duke, Magenta Tubular, other clear pink | J31: No | K31: All pinks, Benary Red | L31: All pinks, Red | M31: pink | N31: all pinks | O31: red | P31: No | Q31: No | R31: Pink, red | S31: Pink | T31: No | U31: No | V31: No | W31: Pink, Red | X31: Pink | Y31: Rose | Z31: Pink | AA31: No | AB31: No | AC31: Red | AD31: pink | AE31: No | AF31: All pinks | AG31: No | AH31: Yes | AI31: No | AJ31: Yes | AK31: No | AL31: Yes | AM31: Yes | AN31: Yes | AO31: Yes | AP31: No
A32: Hydrangea (M) | D32: Rainbow Sherbet | E32: peach, orange, pink, white | F32: No | G32: No | H32: Pinks, orange | I32: orange, Doris Duke, other clear pink | J32: No | K32: Pink, orange | L32: Bright pink (not purple-y), orange | M32: No | N32: pink, white | O32: No | P32: No | Q32: White | R32: Pink, orange, white | S32: pink, orange | T32: Orange | U32: No | V32: Yes | W32: Pink | X32: Limelight | Y32: No | Z32: Pink | AA32: No | AB32: White | AC32: Orange | AD32: White, pink | AE32: No | AF32: Pink, orange | AG32: No | AH32: Yes | AI32: No | AJ32: Yes | AK32: No | AL32: Yes | AM32: Yes | AN32: Yes | AO32: Yes | AP32: Yes
A33: Statice | C33: add white | D33: Firecracker | E33: Red, bright pink, orange, purple | F33: No | G33: No | H33: Benary Bright pink, Benary orange, Benary purple, Benary red | I33: Purple-pink spiky, Hula, Thomas Edison, Purple Keeper, Magenta Tubular, Cornel, Fabulous | J33: No | K33: Bright pink, Bright orange, purple, red | L33: Bright pink, red, orange, purple | M33: No | N33: Nightengale, Arena Red | O33: Red | P33: No | Q33: No | R33: bright pink, orange, red, purple | S33: burgundy, orange | T33: Orange | U33: No | V33: No | W33: Pink, Red, Purple | X33: No | Y33: purple | Z33: Pink, Coral | AA33: No | AB33: dark purple, | AC33: Dark Purple, Bright pink, Red, Orange | AD33: No | AE33: Yes | AF33: No | AG33: Burgundy | AH33: Yes | AI33: No | AJ33: Yes | AK33: Yes | AL33: Yes | AM33: Yes | AN33: Yes | AO33: Yes | AP33: Yes
A34: Yarrow | C34: add white | D34: Campfire | E34: Red, bright pink, orange, burgundy | F34: No | G34: No | H34: Benary Bright pink, Benary orange, Benary burgundy, Benary red | I34: SP Burgundy, Cornel, Orange, Magenta Tubular, Fabulous | J34: No | K34: Bright pink, Bright orange, burgundy, red | L34: Bright pink, red, orange, burgundy | M34: No | N34: Nightengale, Arena Red | O34: Red | P34: No | Q34: No | R34: bright pink, orange, red | S34: burgundy, orange | T34: Orange | U34: No | V34: No | W34: Red, Burgundy | X34: No | Y34: No | Z34: Pink, Coral | AA34: No | AB34: Rubenza | AC34: Red, Orange | AD34: Burgundy | AE34: No | AF34: No | AG34: Burgundy | AH34: Yes | AI34: No | AJ34: Yes | AK34: Yes | AL34: Yes | AM34: Yes | AN34: Yes | AO34: Yes | AP34: Yes
A35: Brain Celosia | D35: Sugar Plum Fairy | E35: lavender, cream, purple, purple-pink | F35: No | G35: No | H35: Benary Lilac, Benary Purple | I35: lavenders, spiky pink-purple, Hula, Purple Keeper, Magenta Tubular, Thomas Edison | J35: No | K35: Lilac, Purple | L35: Purples | M35: No | N35: light blue | O35: No | P35: No | Q35: No | R35: purple | S35: Burgundy | T35: No | U35: No | V35: No | W35: Purple | X35: Pinky-purple | Y35: purple | Z35: cool pink | AA35: No | AB35: lilac, purple | AC35: light purple, dark purple | AD35: No | AE35: Yes | AF35: No | AG35: No | AH35: Yes | AI35: No | AJ35: Yes | AK35: No | AL35: Yes | AM35: Yes | AN35: Yes | AO35: Yes | AP35: Yes
A36: Indigo | B36: Oklahoma salmon zinnias and Rudbeckia overlap | D36: Sunkissed | E36: Salmon and Gold | F36: No | G36: Orange | H36: Benary | I36: Robin Hood, Rose Toscano | J36: Orange | K36: Oklahoma Salmon | L36: No | M36: Gold | N36: Apricot | O36: No | P36: Goldilocks | Q36: No | R36: No | S36: Apricot | T36: No | U36: Yes | V36: Yes | W36: Gold | X36: Pink | Y36: No | Z36: Peach | AA36: No | AB36: No | AC36: No | AD36: No | AE36: No | AF36: Salmon | AG36: No | AH36: Yes | AI36: Yes | AJ36: Yes | AK36: Yes | AL36: Yes | AM36: Yes | AN36: Yes | AO36: Yes | AP36: Yes
A37: 4 - Float
A38: Ageratum
A39: Cosmos | D39: Stems/bouquet | F39: 1 | G39: 1 | H39: 1 | J39: 2 | K39: 1 | L39: 1 | M39: 2 | N39: 0.5 | O39: 0.5 | P39: 1 | Q39: 2 | R39: 1 | S39: 0.5 | U39: 0.5 | V39: 0.5 | W39: 1 | X39: 0.5 | Y39: 0.5 | Z39: 0.25 | AA39: 0.5 | AB39: 0.25 | AC39: 1 | AD39: 0.5
A40: Gomphrena | AA40: white only
A41: Scabiosa | D41: things we don't need much of with this color palette | G41: purple cosmos
...

Sheet Fall
A1: Season | B1: (Multiple Items) | I1: total # of regular market bouquets desired = | J1: 50 | L1: total # of large bouquets desired | M1: 10 | O1: total # of small bouquets desired | P1: 10
O2: =MIN($D$24) -> 55.962819
A3: Row Labels | F3: 1. Fill in the cells in orange. Do NOT adjust any other values | O3: =COUNT($E$24:$E$29) -> 6
A4: 1 - Focal | F4: 2. Run "solver". Go to the "Data" tab. | O4: =$D$24<=37 -> FALSE
A5: Dahlia (L) | F5: 3. Click on cell D13-D18 (it is a merged cell) | O5: =$D$24>=34.5 -> TRUE
A6: Delphinium | F6: 4. In the upper right, click on "Analysis Tools". Note: if you see "Solver" in the upper right, you can skip this step. | O6: =$E$24<=3 -> FALSE
A7: Garden Rose | F7: 5. Check the box for "Solver." | O7: =$E$24>=2 -> TRUE
A8: Sunflower (M-L) | F8: 6. Hit "Solve" in the lower right | O8: {=$E$24:$E$29=INT($E$24:$E$29)} -> TRUE
A9: Zinnia (XL) | O9: =$E$25>=3 -> TRUE
A10: 2 - Foundation | O10: =$E$26<=2 -> FALSE
A11: Celosia | O11: =$E$26>=1 -> TRUE
A12: Dahlia (M) | B12: Regular ($30 wholesale) Bouquets | E12: Calculated quantity of flowers in bouquet | F12: total number of stems used | I12: average wholesale price for category | J12: Availability (# stems) | L12: # stems leftover | O12: =$E$27=3 -> FALSE
A13: Dahlia (S) | C13: Fall | D13: =SUMPRODUCT(E13:E18, I13:I18) -> 34.883142 | E13: 3 | F13: =$M$1*E13 -> 30 | H13: focal | I13: =AVERAGEIFS('Master Variety List'!E:E, 'Master Variety List'!A:A, "*Fall*", 'Master Variety List'!B:B, "*Focal*") -> 2.6453333 | J13: 400 | L13: =J13-F13 -> 370 | O13: =$E$28>=1 -> TRUE
A14: Echinacea | E14: 7 | F14: =$M$1*E14 -> 70 | H14: foundation | I14: =AVERAGEIFS('Master Variety List'!E:E, 'Master Variety List'!A:A, "*Fall*", 'Master Variety List'!B:B, "*Foundation*") -> 1.6591883 | J14: 400 | L14: =J14-F14 -> 330 | O14: =$E$29=3 -> FALSE
A15: Garden Rose | E15: 1 | F15: =$M$1*E15 -> 10 | H15: filler | I15: =AVERAGEIFS('Master Variety List'!E:E, 'Master Variety List'!A:A, "*Fall*", 'Master Variety List'!B:B, "*Filler*") -> 1.6082895 | J15: 120 | L15: =J15-F15 -> 110 | O15: =$F$24<=$J$24 -> TRUE
A16: Lisianthus | E16: 3 | F16: =$M$1*E16 -> 30 | H16: float | I16: =AVERAGEIFS('Master Variety List'!E:E, 'Master Variety List'!A:A, "*Fall*", 'Master Variety List'!B:B, "*Float*") -> 1.3608333 | J16: 200 | L16: =J16-F16 -> 170 | O16: =$F$25<=$J$25 -> TRUE
A17: Queen Anne's / Ammi | E17: 3 | F17: =$M$1*E17 -> 30 | H17: finisher | I17: =AVERAGEIFS('Master Variety List'!E:E, 'Master Variety List'!A:A, "*Fall*", 'Master Variety List'!B:B, "*Finisher*") -> 1.7747807 | J17: 250 | L17: =J17-F17 -> 220 | O17: =$F$26<=$J$26 -> TRUE
A18: Snapdragon (L) | E18: 3 | F18: =$M$1*E18 -> 30 | H18: foliage | I18: =AVERAGEIFS('Master Variety List'!E:E, 'Master Variety List'!A:A, "*Fall*", 'Master Variety List'!B:B, "*Foliage*") -> 1.4392308 | J18: 300 | L18: =J18-F18 -> 270 | O18: =$F$27<=$J$27 -> TRUE
A19: Snapdragon (S) | O19: =$F$28<=$J$28 -> TRUE
A20: Strawflower | O20: =$F$29<=$J$29 -> TRUE
A21: Zinnia (M-L) | O21: ={32767,32767,0.000001,0.01,FALSE,FALSE,TRUE,1,1,1,0.0001,TRUE} -> 32767
A22: Marigold | O22: ={0,0,0,100,0,FALSE,TRUE,0.075,0,0,FALSE,30} -> 0
A23: Thistle | B23: Large ($50 wholesale) Bouquets | E23: Calculated quantity of flowers in bouquet | F23: total number of stems used | I23: average wholesale price for category | J23: Availability (# stems) | L23: # stems leftover
A24: 2 -Foundation | C24: Fall | D24: =SUMPRODUCT(I24:I29, E24:E29) -> 55.962819 | E24: 5 | F24: =$M$1*E24 -> 50 | H24: focal | I24: =AVERAGEIFS('Master Variety List'!E:E, 'Master Variety List'!A:A, "*Fall*", 'Master Variety List'!B:B, "*Focal*") -> 2.6453333 | J24: =L13 -> 370 | L24: =J24-F24 -> 320
A25: Sunflower (S) | E25: 11 | F25: =$M$1*E25 -> 110 | H25: foundation | I25: =AVERAGEIFS('Master Variety List'!E:E, 'Master Variety List'!A:A, "*Fall*", 'Master Variety List'!B:B, "*Foundation*") -> 1.6591883 | J25: =L14 -> 330 | L25: =J25-F25 -> 220
A26: 3 - Filler | E26: 3 | F26: =$M$1*E26 -> 30 | H26: filler | I26: =AVERAGEIFS('Master Variety List'!E:E, 'Master Variety List'!A:A, "*Fall*", 'Master Variety List'!B:B, "*Filler*") -> 1.6082895 | J26: =L15 -> 110 | L26: =J26-F26 -> 80
A27: Greek Oregano | E27: 5 | F27: =$M$1*E27 -> 50 | H27: float | I27: =AVERAGEIFS('Master Variety List'!E:E, 'Master Variety List'!A:A, "*Fall*", 'Master Variety List'!B:B, "*Float*") -> 1.3608333 | J27: =L16 -> 170 | L27: =J27-F27 -> 120
A28: Hydrangea (M) | E28: 4 | F28: =$M$1*E28 -> 40 | H28: finisher | I28: =AVERAGEIFS('Master Variety List'!E:E, 'Master Variety List'!A:A, "*Fall*", 'Master Variety List'!B:B, "*Finisher*") -> 1.7747807 | J28: =L17 -> 220 | L28: =J28-F28 -> 180
A29: Statice | E29: 4 | F29: =$M$1*E29 -> 40 | H29: foliage | I29: =AVERAGEIFS('Master Variety List'!E:E, 'Master Variety List'!A:A, "*Fall*", 'Master Variety List'!B:B, "*Foliage*") -> 1.4392308 | J29: =L18 -> 270 | L29: =J29-F29 -> 230
A30: Brain Celosia
A31: Indigo
A32: 4 - Float
A33: Ageratum | B33: Small ($20 wholesale) Bouquets | E33: Calculated quantity of flowers in bouquet | F33: total number of stems used | I33: average price for category | J33: Availability (# stems) | L33: # stems leftover
A34: Cosmos | C34: Fall | D34: =SUMPRODUCT(E34:E39, I34:I39) -> 21.882017 | E34: 1 | F34: =$P$1*E34 -> 10 | H34: focal | I34: =AVERAGEIFS('Master Variety List'!E:E, 'Master Variety List'!A:A, "*Fall*", 'Master Variety List'!B:B, "*Focal*") -> 2.6453333 | J34: =L24 -> 320 | L34: =J34-F34 -> 310
A35: Gomphrena | E35: 7 | F35: =$P$1*E35 -> 70 | H35: foundation | I35: =AVERAGEIFS('Master Variety List'!E:E, 'Master Variety List'!A:A, "*Fall*", 'Master Variety List'!B:B, "*Foundation*") -> 1.6591883 | J35: =L25 -> 220 | L35: =J35-F35 -> 150
A36: Scabiosa | E36: 1 | F36: =$P$1*E36 -> 10 | H36: filler | I36: =AVERAGEIFS('Master Variety List'!E:E, 'Master Variety List'!A:A, "*Fall*", 'Master Variety List'!B:B, "*Filler*") -> 1.6082895 | J36: =L26 -> 80 | L36: =J36-F36 -> 70
A37: Scabiosa Pod | E37: 1 | F37: =$P$1*E37 -> 10 | H37: float | I37: =AVERAGEIFS('Master Variety List'!E:E, 'Master Variety List'!A:A, "*Fall*", 'Master Variety List'!B:B, "*Float*") -> 1.3608333 | J37: =L27 -> 120 | L37: =J37-F37 -> 110
A38: Zinnia (XS) | E38: 1 | F38: =$P$1*E38 -> 10 | H38: finisher | I38: =AVERAGEIFS('Master Variety List'!E:E, 'Master Variety List'!A:A, "*Fall*", 'Master Variety List'!B:B, "*Finisher*") -> 1.7747807 | J38: =L28 -> 180 | L38: =J38-F38 -> 170
A39: Thistle | E39: 2 | F39: =$P$1*E39 -> 20 | H39: foliage | I39: =AVERAGEIFS('Master Variety List'!E:E, 'Master Variety List'!A:A, "*Fall*", 'Master Variety List'!B:B, "*Foliage*") -> 1.4392308 | J39: =L29 -> 230 | L39: =J39-F39 -> 210
A40: Indigo
...

Sheet Formula Expt.
O1: loaded scenario below
O2: =MIN($O$1) -> 0
O3: =COUNT($C$11:$C$16) -> 0
A4: Early Spring | B4: =SUMPRODUCT(G4:G9, C4:C9) -> 0 | O4: =$B$11<=37 -> TRUE
O5: =$B$11>=35 -> FALSE
O6: =$C$11<=2 -> TRUE
O7: =$C$11>=1 -> FALSE
O8: {=$C$11:$C$16=INT($C$11:$C$16)} -> TRUE
O9: =$C$12>=3 -> FALSE
O10: =$C$13<=2 -> TRUE
A11: Late Spring | B11: =SUMPRODUCT(G11:G16, C11:C16) -> 0 | O11: =$C$13>=1 -> FALSE
O12: =$C$14<=3 -> TRUE
O13: =$C$14>=2 -> FALSE
O14: =$C$15<=2 -> TRUE
O15: =$C$16<=3 -> TRUE
O16: =$C$16>=2 -> FALSE
O17: =$D$11<=$H$11 -> TRUE
A18: Summer | B18: =SUMPRODUCT(G18:G23, C18:C23) -> 0 | O18: =$D$12<=$H$12 -> TRUE
O19: =$D$13<=$H$13 -> TRUE
O20: =$D$14<=$H$14 -> TRUE
O21: =$D$15<=$H$15 -> TRUE
O22: =$D$16<=$H$16 -> TRUE
O23: ={32767,32767,0.000001,0.01,FALSE,FALSE,TRUE,1,1,1,0.0001,TRUE} -> 32767
O24: ={0,0,0,100,0,FALSE,TRUE,0.075,0,0,FALSE,30} -> 0
D33: Season | E33: Category | F33: Flower | G33: Retail Price | H33: Avg. WS Price | I33: MVFC | J33: Potomac | K33: SP Guess
D34: Summer, Fall | E34: 1 - Focal | F34: Sunflower (M-L) | G34: =H34*(1+$E$1) -> 1.99 | H34: =AVERAGE(I34:K34) -> 1.99 | J34: 1.99
D35: Summer, Fall | E35: 1 - Focal | F35: Zinnia (XL) | G35: =H35*(1+$E$1) -> 1.65 | H35: =AVERAGE(I35:K35) -> 1.65 | K35: 1.65
D36: Fall | E36: 1 - Focal | F36: Dahlia (L) | G36: =H36*(1+$E$1) -> 2.6 | H36: =AVERAGE(I36:K36) -> 2.6 | J36: 2.6
D37: Early Spring | E37: 1 - Focal | F37: Tulip - French | G37: =H37*(1+$E$1) -> 4.1 | H37: =AVERAGE(I37:K37) -> 4.1 | K37: 4.1 | M37: Summer/Fall | N37: Focal | O37: Average of All Varieties | P37: =AVERAGE(G34:G36) -> 2.08 | Q37: =AVERAGE(H34:H36) -> 2.08
D38: Early Spring | E38: 1 - Focal | F38: Tulip - Double | G38: =H38*(1+$E$1) -> 4.3 | H38: =AVERAGE(I38:K38) -> 4.3 | K38: 4.3 | M38: Spring | N38: Focal | O38: Average of All Varieties | P38: =AVERAGE(G40:G44) -> 3.81 | Q38: =AVERAGE(H37:H39) -> 4.125
D39: Early Spring | E39: 1 - Focal | F39: Tulip - Regular | G39: =H39*(1+$E$1) -> 3.975 | H39: =AVERAGE(I39:K39) -> 3.975 | I39: 4 | J39: 3.95 | M39: Early Spring | N39: Focal | O39: Average of All Varieties | P39: =AVERAGE(G37:G39) -> 4.125 | Q39: =AVERAGE(H41:H114) -> 1.5783211
D40: Late Spring | E40: 1 - Focal | F40: Peony - Coral Charm | G40: =H40*(1+$E$1) -> 3.975 | H40: =AVERAGE(I40:K40) -> 3.975 | I40: 4 | J40: 3.95
D41: Late Spring | E41: 1 - Focal | F41: Peony - Dark Pink | G41: =H41*(1+$E$1) -> 4.475 | H41: =AVERAGE(I41:K41) -> 4.475 | I41: 4 | J41: 4.95
D42: Late Spring | E42: 1 - Focal | F42: Peony - Pink | G42: =H42*(1+$E$1) -> 3.3 | H42: =AVERAGE(I42:K42) -> 3.3 | I42: 3 | J42: 3.6
D43: Late Spring | E43: 1 - Focal | F43: Peony - Pale Pink/Blush | G43: =H43*(1+$E$1) -> 3.975 | H43: =AVERAGE(I43:K43) -> 3.975 | I43: 4 | J43: 3.95 | M43: Early Spring | N43: April, early May
D44: Late Spring | E44: 1 - Focal | F44: Peony - White | G44: =H44*(1+$E$1) -> 3.325 | H44: =AVERAGE(I44:K44) -> 3.325 | I44: 3 | J44: 3.65 | M44: Late Spring | N44: Late May, June
D45: Late Spring, Summer, Fall | E45: 1 - Focal | F45: Delphinium | G45: =H45*(1+$E$1) -> 1.7 | H45: =AVERAGE(I45:K45) -> 1.7 | I45: 1.4 | J45: 2
M46: Summer | N46: July, August
D47: Summer, Fall | E47: 2 -Foundation | F47: Sunflower (S) | G47: =H47*(1+$E$1) -> 1 | H47: =AVERAGE(I47:K47) -> 1 | J47: 1 | M47: Fall | N47: September, October
D48: Late Spring, Fall | E48: 2 - Foundation | F48: Garden Rose | G48: =H48*(1+$E$1) -> 1.79 | H48: =AVERAGE(I48:K48) -> 1.79 | J48: 1.79
...

Sheet Varieties By Season
B2: Bloom Start Month | C2: Sequence | D2: Variety | E2: March | H2: April | K2: May | N2: June | Q2: July | T2: August | W2: September | Z2: October
C3: Seeding | D3: Tulip
C4: Planting
C5: Blooming
C6: Seeding | D6: Tulip
C7: Planting
C8: Blooming
C9: Seeding | D9: Tulip
C10: Planting
C11: Blooming
C12: Seeding | D12: Stock
C13: Planting
C14: Blooming
C15: Seeding | D15: Baptisia
C16: Planting
C17: Blooming
C18: Seeding | D18: Privet
C19: Planting
C20: Blooming
C21: Seeding | D21: Ranunculus
C22: Planting
C23: Blooming
C24: Seeding | D24: Anemone
C25: Planting
C26: Blooming
C27: Seeding
C28: Planting
C29: Blooming
C30: Seeding
C31: Planting
C32: Blooming
C33: Seeding
C34: Planting
C35: Blooming
C36: Seeding
... C56: Blooming

Sheet Old Flower List
B1: IMPORTANT: As of 12/23/23 this sheet is now out of date -- please don't use. See "Master Variety List" tab instead.
B2: Phlox (fill rest of rudbeckia row) | C2: Hyacinth Beans (end-August - September) | D2: Deutzia - Early May | F2: Pieris - April
B3: o | E3: Retail Markup | F3: 0.5
B5: Season | C5: Notes For Next Year | D5: Season | E5: Category | F5: Flower | G5: Retail Price | H5: Avg. WS Price | I5: MVFC | J5: Potomac | K5: SP Guess | L5: asdf
B6: July - October | C6: If in June, plant white nights first, otherwise plant whites and yellows at same time for both successions | D6: Summer/Fall | E6: 1 - Focal | F6: Sunflower (M-L) | G6: =H6*(1+$F$3) -> 2.985 | H6: =AVERAGE(I6:K6) -> 1.99 | J6: 1.99
B7: Mid-July - October | D7: Summer/Fall | E7: 1 - Focal | F7: Zinnia (XL) | G7: =H7*(1+$F$3) -> 3.3 | H7: =AVERAGE(I7:K7) -> 2.2 | K7: 2.2
B8: August - October | D8: Summer/Fall | E8: 1 - Focal | F8: Dahlia (XL) | G8: =H8*(1+$F$3) -> 6.75 | H8: =AVERAGE(I8:K8) -> 4.5 | I8: 4.5 | M8: *we charged $6 retail for single dahlia stem in bouquet on 8/23/23 - not on average for recipes
B9: August - October | D9: Summer/Fall | E9: 1 - Focal | F9: Dahlia (L) | G9: =H9*(1+$F$3) -> 3.9 | H9: =AVERAGE(I9:K9) -> 2.6 | J9: 2.6
B10: March - Early May | C10: Better watering | D10: Spring | E10: 1 - Focal | F10: Tulip - French | G10: =H10*(1+$F$3) -> 6.15 | H10: =AVERAGE(I10:K10) -> 4.1 | K10: 4.1
B11: March - Early May | C11: Better watering | D11: Spring | E11: 1 - Focal | F11: Tulip - Double | G11: =H11*(1+$F$3) -> 6.45 | H11: =AVERAGE(I11:K11) -> 4.3 | K11: 4.3
B12: March - Early May | C12: Better watering | D12: Spring | E12: 1 - Focal | F12: Tulip - Regular | G12: =H12*(1+$F$3) -> 5.9625 | H12: =AVERAGE(I12:K12) -> 3.975 | I12: 4 | J12: 3.95
B13: Late May - June | C13: If lucky, mid may for Mother's Day | D13: Spring | E13: 1 - Focal | F13: Peony - Coral Charm | G13: =H13*(1+$F$3) -> 5.9625 | H13: =AVERAGE(I13:K13) -> 3.975 | I13: 4 | J13: 3.95 | M13: *not on average for recipes
B14: Late May - June | D14: Spring | E14: 1 - Focal | F14: Peony - Dark Pink | G14: =H14*(1+$F$3) -> 6.7125 | H14: =AVERAGE(I14:K14) -> 4.475 | I14: 4 | J14: 4.95 | M14: *not on average for recipes
B15: Late May - June | D15: Spring | E15: 1 - Focal | F15: Peony - Pink | G15: =H15*(1+$F$3) -> 4.95 | H15: =AVERAGE(I15:K15) -> 3.3 | I15: 3 | J15: 3.6 | M15: *not on average for recipes
B16: Late May - June | D16: Spring | E16: 1 - Focal | F16: Peony - Pale Pink/Blush | G16: =H16*(1+$F$3) -> 5.9625 | H16: =AVERAGE(I16:K16) -> 3.975 | I16: 4 | J16: 3.95 | M16: *not on average for recipes
B17: Late May - June | D17: Spring | E17: 1 - Focal | F17: Peony - White | G17: =H17*(1+$F$3) -> 4.9875 | H17: =AVERAGE(I17:K17) -> 3.325 | I17: 3 | J17: 3.65 | M17: *not on average for recipes
B18: July - October | D18: Summer/Fall | E18: 2 - Support | F18: Sunflower (S) | G18: =H18*(1+$F$3) -> 1.5 | H18: =AVERAGE(I18:K18) -> 1 | J18: 1
C19: Need serious remediation | D19: Summer/Fall | E19: 2 - Support | F19: Garden Rose | G19: =H19*(1+$F$3) -> 2.685 | H19: =AVERAGE(I19:K19) -> 1.79 | J19: 1.79
B20: August - October | D20: Summer/Fall | E20: 2 - Support | F20: Dahlia (S) | G20: =H20*(1+$F$3) -> 3.15 | H20: =AVERAGE(I20:K20) -> 2.1 | K20: 2.1
B21: August - October | D21: Summer/Fall | E21: 2 - Support | F21: Dahlia (M) | G21: =H21*(1+$F$3) -> 4.5 | H21: =AVERAGE(I21:K21) -> 3 | I21: 3
B22: July - October | D22: Summer/Fall | E22: 2 - Support | F22: Strawflower | G22: =H22*(1+$F$3) -> 2.1 | H22: =AVERAGE(I22:K22) -> 1.4 | I22: 1.4
B23: June - July | D23: Summer/Fall | E23: 2 - Support | F23: Queen Anne's / Ammi | G23: =H23*(1+$F$3) -> 1.875 | H23: =AVERAGE(I23:K23) -> 1.25 | I23: 1.3 | J23: 1.2
B24: July - August | D24: Summer/Fall | E24: 2 - Support | F24: Echinacea | G24: =H24*(1+$F$3) -> 1.5 | H24: =AVERAGE(I24:K24) -> 1 | K24: 1
B25: July - September (maybe October) | C25: Shar wants goldilocks + mini ones but we have so much already | D25: Summer/Fall | E25: 2 - Support | F25: Rudbeckia | G25: =H25*(1+$F$3) -> 1.8 | H25: =AVERAGE(I25:K25) -> 1.2 | I25: 1.4 | K25: 1
B26: July - September (maybe October) | D26: Summer/Fall | E26: 2 - Support | F26: Scabiosa (Fama) | G26: =H26*(1+$F$3) -> 2.1 | H26: =AVERAGE(I26:K26) -> 1.4 | K26: 1.4
B27: Mid-July - October | D27: Summer/Fall | E27: 2 - Support | F27: Zinnia (M-L) | G27: =H27*(1+$F$3) -> 1.65 | H27: =AVERAGE(I27:K27) -> 1.1 | I27: 1.2 | K27: 1
B28: July - August... mid-Sept - October | C28: Double flush, tunneled potentially or rain cover | D28: Summer/Fall | E28: 2 - Support | F28: Lisianthus | G28: =H28*(1+$F$3) -> 3.35625 | H28: =AVERAGE(I28:K28) -> 2.2375 | I28: =17.25/10 -> 1.725 | J28: 2.75
B29: June - July | D29: Summer/Fall | E29: 2 - Support | F29: Lupine | G29: =H29*(1+$F$3) -> 2.5875 | H29: =AVERAGE(I29:K29) -> 1.725 | I29: 1.55 | J29: 1.9
B30: June - July... Sept - October | C30: Need more blush + white, tunneled if we want earlier, multiple successions | D30: Summer/Fall | E30: 2 - Support | F30: Snapdragon (S) | G30: =H30*(1+$F$3) -> 2.4 | H30: =AVERAGE(I30:K30) -> 1.6 | J30: 1.6
B31: June - July... Sept - October | C31: Need more blush + white, tunneled if we want earlier, multiple successions | D31: Summer/Fall | E31: 2 - Support | F31: Snapdragon (L) | G31: =H31*(1+$F$3) -> 3.6 | H31: =AVERAGE(I31:K31) -> 2.4 | J31: 2.4
B32: Mid-July - October | D32: Summer/Fall | E32: 2 - Support | F32: Amaranth | G32: =H32*(1+$F$3) -> 2.2575 | H32: =AVERAGE(I32:K32) -> 1.505 | I32: 1.3 | J32: 1.71
B33: August - October | D33: Summer/Fall | E33: 2 - Support | F33: Celosia | G33: =H33*(1+$F$3) -> 2.4 | H33: =AVERAGE(I33:K33) -> 1.6 | I33: 1.4 | J33: 1.8
B34: April - mid-June | D34: Spring | E34: 2 - Support | F34: Ranunculus | G34: =H34*(1+$F$3) -> 3.075 | H34: =AVERAGE(I34:K34) -> 2.05 | J34: 2.05
B35: April - mid-June | D35: Spring | E35: 2 - Support | F35: Anemone | G35: =H35*(1+$F$3) -> 2.85 | H35: =AVERAGE(I35:K35) -> 1.9 | J35: 1.9
B36: Mid-April - June | D36: Spring | E36: 2 - Support | F36: Poppy - Icelandic (M-L) | G36: =H36*(1+$F$3) -> 2.25 | H36: =AVERAGE(I36:K36) -> 1.5 | K36: =15/10 -> 1.5
B37: Mid-April - June | D37: Spring | E37: 2 - Support | F37: Daffodil | G37: =H37*(1+$F$3) -> 1.425 | H37: =AVERAGE(I37:K37) -> 0.95 | K37: =9.5/10 -> 0.95
B38: April | D38: Spring | E38: 2 - Support | F38: Orlaya | G38: =H38*(1+$F$3) -> 1.5 | H38: =AVERAGE(I38:K38) -> 1 | I38: 1.1 | J38: 0.9
B39: Late March - June | C39: Extend season by selecting ones that are known for early vs. mid season, using the sacata guide Sharon put in Notion | D39: Spring | E39: 2 - Support | F39: Stock | G39: =H39*(1+$F$3) -> 2.175 | H39: =AVERAGE(I39:K39) -> 1.45 | I39: 1.4 | J39: 1.5
B40: June - August (maybe September) | D40: Spring | E40: 2 - Support | F40: Delphinium | G40: =H40*(1+$F$3) -> 2.55 | H40: =AVERAGE(I40:K40) -> 1.7 | I40: 1.4 | J40: 2
B41: Early - Mid June | C41: Lets pack shade garden so less weeds!!!!!! YAY!!!!!! | D41: Spring | E41: 2 - Support | F41: Astilbe - Pale Pink | G41: =H41*(1+$F$3) -> 1.6875 | H41: =AVERAGE(I41:K41) -> 1.125 | I41: 0.75 | J41: 1.5
...

Sheet Sheet1
B2: Column1 | C2: Season | D2: Notes For Next Year | E2: Season2 | F2: Category | G2: Flower | H2: Column3
B3: 1 | C3: March - Early May | D3: Better watering | E3: Spring | F3: 1 - Focal | G3: Tulip - French
B4: 1 | C4: March - Early May | D4: Better watering | E4: Spring | F4: 1 - Focal | G4: Tulip - Double
B5: 1 | C5: March - Early May | D5: Better watering | E5: Spring | F5: 1 - Focal | G5: Tulip - Regular
B6: 1 | C6: Late March - June | D6: Extend season by selecting ones that are known for early vs. mid season, using the sacata guide Sharon put in Notion | E6: Spring | F6: 2 - Support | G6: Stock
B7: 1 | C7: End of March - April, maybe earlyMay?? | E7: Spring | F7: 2 - Support | G7: Baptisia
B8: 1 | C8: March - June | E8: Spring | G8: Privet
B9: 2 | C9: April - mid-June | E9: Spring | F9: 2 - Support | G9: Ranunculus
B10: 2 | C10: April - mid-June | E10: Spring | F10: 2 - Support | G10: Anemone
B11: 2 | C11: Mid-April - June | E11: Spring | F11: 2 - Support | G11: Poppy - Icelandic (M-L)
B12: 2 | C12: Mid-April - June | E12: Spring | F12: 2 - Support | G12: Daffodil
B13: 2 | C13: April | E13: Spring | F13: 2 - Support | G13: Orlaya
B14: 2 | C14: April - May | E14: Spring | F14: 4 - Float | G14: Bleeding Heart
B15: 2 | C15: Mid-April - June | E15: Spring | F15: 4 - Float | G15: Iceland poppy (small)
B16: 2 | C16: April - October | E16: Summer/Fall | F16: 5 - Finisher | G16: Papyrus
B17: 2 | C17: April-May | E17: Spring | F17: 5 - Foliage | G17: Euonymous
B18: 3 | C18: Late May - June | D18: If lucky, mid may for Mother's Day | E18: Spring | F18: 1 - Focal | G18: Peony - Coral Charm
B19: 3 | C19: Late May - June | E19: Spring | F19: 1 - Focal | G19: Peony - Dark Pink
B20: 3 | C20: Late May - June | E20: Spring | F20: 1 - Focal | G20: Peony - Pink
B21: 3 | C21: Late May - June | E21: Spring | F21: 1 - Focal | G21: Peony - Pale Pink/Blush
B22: 3 | C22: Late May - June | E22: Spring | F22: 1 - Focal | G22: Peony - White
B23: 3 | C23: End of May - Mid June | E23: Spring | F23: 2 - Support | G23: Larkspur
B24: 3 | C24: May | D24: Move double plants somewhere else | E24: Spring | F24: 3 - Filler | G24: Mock Orange
B25: 3 | C25: May | E25: Spring | F25: 3 - Filler | G25: Spirea
B26: 3 | C26: May - June | E26: Spring | F26: 4 - Float | G26: Bupleurum
B27: 3 | C27: May - June | E27: Spring | F27: 4 - Float | G27: Bachelor's Buttons
B28: 3 | C28: May | E28: Spring | F28: 4 - Float | G28: Agrostemma
B29: 3 | C29: Early May | E29: Spring | F29: 5 - Finisher | G29: Allium
B30: 3 | C30: Mid-May | E30: Spring | F30: 5 - Finisher | G30: Dogwood Branch
B31: 3 | C31: May-June | D31: STOP IT, Carla to find finisher equivalent | E31: Spring | F31: 5 - Finisher | G31: Saponaria
B32: 3 | C32: May - July | E32: Summer/Fall | F32: 5 - Foliage | G32: Mint
B33: 3 | C33: May | E33: Spring | F33: 5 - Foliage | G33: Snowberry
B34: 3 | C34: May - June | E34: Spring | F34: 5 - Foliage | G34: Honeysuckle
B35: 3 | C35: May | E35: Spring | G35: Snowball Viburnum
B36: 3 | C36: May-June | G36: Pansy
B37: 3 | C37: May-June | E37: Spring | G37: Sweet Pea
B38: 4 | C38: June - July | E38: Summer/Fall | F38: 2 - Support | G38: Queen Anne's / Ammi
B39: 4 | C39: June - July | E39: Summer/Fall | F39: 2 - Support | G39: Lupine
B40: 4 | C40: June - July... Sept - October | D40: Need more blush + white, tunneled if we want earlier, multiple successions | E40: Summer/Fall | F40: 2 - Support | G40: Snapdragon (S)
B41: 4 | C41: June - July... Sept - October | D41: Need more blush + white, tunneled if we want earlier, multiple successions | E41: Summer/Fall | F41: 2 - Support | G41: Snapdragon (L)
...

Sheet LFL - Lisianthus
B1: Phlox (fill rest of rudbeckia row) | C1: Hyacinth Beans (end-August - September) | D1: Deutzia - Early May | F1: Pieris - April
B2: Indigo (September - October) | E2: Retail Markup | F2: 0.5
B4: Season | C4: Notes For Next Year | D4: Season | E4: Category | F4: Flower | G4: Retail Price | H4: Avg. WS Price | I4: MVFC | J4: Potomac | K4: SP Guess | L4: asdf
B5: July - October | C5: If in June, plant white nights first, otherwise plant whites and yellows at same time for both successions | D5: Summer/Fall | E5: 1 - Focal | F5: Sunflower (M-L) | G5: =H5*(1+$F$2) -> 2.985 | H5: =AVERAGE(I5:K5) -> 1.99 | J5: 1.99
B6: Mid-July - October | D6: Summer/Fall | E6: 1 - Focal | F6: Zinnia (XL) | G6: =H6*(1+$F$2) -> 3.3 | H6: =AVERAGE(I6:K6) -> 2.2 | K6: 2.2
B7: August - October | D7: Summer/Fall | E7: 1 - Focal | F7: Dahlia (XL) | G7: =H7*(1+$F$2) -> 6.75 | H7: =AVERAGE(I7:K7) -> 4.5 | I7: 4.5 | M7: *we charged $6 retail for single dahlia stem in bouquet on 8/23/23 - not on average for recipes
B8: August - October | D8: Summer/Fall | E8: 1 - Focal | F8: Dahlia (L) | G8: =H8*(1+$F$2) -> 3.9 | H8: =AVERAGE(I8:K8) -> 2.6 | J8: 2.6
B9: March - Early May | C9: Better watering | D9: Spring | E9: 1 - Focal | F9: Tulip - French | G9: =H9*(1+$F$2) -> 6.15 | H9: =AVERAGE(I9:K9) -> 4.1 | K9: 4.1
B10: March - Early May | C10: Better watering | D10: Spring | E10: 1 - Focal | F10: Tulip - Double | G10: =H10*(1+$F$2) -> 6.45 | H10: =AVERAGE(I10:K10) -> 4.3 | K10: 4.3
B11: March - Early May | C11: Better watering | D11: Spring | E11: 1 - Focal | F11: Tulip - Regular | G11: =H11*(1+$F$2) -> 5.9625 | H11: =AVERAGE(I11:K11) -> 3.975 | I11: 4 | J11: 3.95
B12: Late May - June | C12: If lucky, mid may for Mother's Day | D12: Spring | E12: 1 - Focal | F12: Peony - Coral Charm | G12: =H12*(1+$F$2) -> 5.9625 | H12: =AVERAGE(I12:K12) -> 3.975 | I12: 4 | J12: 3.95 | M12: *not on average for recipes
B13: Late May - June | D13: Spring | E13: 1 - Focal | F13: Peony - Dark Pink | G13: =H13*(1+$F$2) -> 6.7125 | H13: =AVERAGE(I13:K13) -> 4.475 | I13: 4 | J13: 4.95 | M13: *not on average for recipes
B14: Late May - June | D14: Spring | E14: 1 - Focal | F14: Peony - Pink | G14: =H14*(1+$F$2) -> 4.95 | H14: =AVERAGE(I14:K14) -> 3.3 | I14: 3 | J14: 3.6 | M14: *not on average for recipes
B15: Late May - June | D15: Spring | E15: 1 - Focal | F15: Peony - Pale Pink/Blush | G15: =H15*(1+$F$2) -> 5.9625 | H15: =AVERAGE(I15:K15) -> 3.975 | I15: 4 | J15: 3.95 | M15: *not on average for recipes
B16: Late May - June | D16: Spring | E16: 1 - Focal | F16: Peony - White | G16: =H16*(1+$F$2) -> 4.9875 | H16: =AVERAGE(I16:K16) -> 3.325 | I16: 3 | J16: 3.65 | M16: *not on average for recipes
B17: July - October | D17: Summer/Fall | E17: 2 - Support | F17: Sunflower (S) | G17: =H17*(1+$F$2) -> 1.5 | H17: =AVERAGE(I17:K17) -> 1 | J17: 1
C18: Need serious remediation | D18: Summer/Fall | E18: 2 - Support | F18: Garden Rose | G18: =H18*(1+$F$2) -> 2.685 | H18: =AVERAGE(I18:K18) -> 1.79 | J18: 1.79
B19: August - October | D19: Summer/Fall | E19: 2 - Support | F19: Dahlia (S) | G19: =H19*(1+$F$2) -> 3.15 | H19: =AVERAGE(I19:K19) -> 2.1 | K19: 2.1
B20: August - October | D20: Summer/Fall | E20: 2 - Support | F20: Dahlia (M) | G20: =H20*(1+$F$2) -> 4.5 | H20: =AVERAGE(I20:K20) -> 3 | I20: 3
B21: July - October | D21: Summer/Fall | E21: 2 - Support | F21: Strawflower | G21: =H21*(1+$F$2) -> 2.1 | H21: =AVERAGE(I21:K21) -> 1.4 | I21: 1.4
B22: June - July | D22: Summer/Fall | E22: 2 - Support | F22: Queen Anne's / Ammi | G22: =H22*(1+$F$2) -> 1.875 | H22: =AVERAGE(I22:K22) -> 1.25 | I22: 1.3 | J22: 1.2
B23: July - August | D23: Summer/Fall | E23: 2 - Support | F23: Echinacea | G23: =H23*(1+$F$2) -> 1.5 | H23: =AVERAGE(I23:K23) -> 1 | K23: 1
B24: July - September (maybe October) | C24: Shar wants goldilocks + mini ones but we have so much already | D24: Summer/Fall | E24: 2 - Support | F24: Rudbeckia | G24: =H24*(1+$F$2) -> 1.8 | H24: =AVERAGE(I24:K24) -> 1.2 | I24: 1.4 | K24: 1
B25: July - September (maybe October) | D25: Summer/Fall | E25: 2 - Support | F25: Scabiosa (Fama) | G25: =H25*(1+$F$2) -> 2.1 | H25: =AVERAGE(I25:K25) -> 1.4 | K25: 1.4
B26: Mid-July - October | D26: Summer/Fall | E26: 2 - Support | F26: Zinnia (M-L) | G26: =H26*(1+$F$2) -> 1.65 | H26: =AVERAGE(I26:K26) -> 1.1 | I26: 1.2 | K26: 1
